#VRML_SIM R2025a utf8

EXTERNPROTO "https://raw.githubusercontent.com/cyberbotics/webots/R2025a/projects/objects/backgrounds/protos/TexturedBackground.proto"
EXTERNPROTO "https://raw.githubusercontent.com/cyberbotics/webots/R2025a/projects/objects/backgrounds/protos/TexturedBackgroundLight.proto"
EXTERNPROTO "https://raw.githubusercontent.com/cyberbotics/webots/R2025a/projects/objects/floors/protos/RectangleArena.proto"

WorldInfo {
  info [
    "Description: DeskBuddy"
  ]
  title "Table"
  basicTimeStep 16
  lineScale 0.2
}
Viewpoint {
  orientation -0.01855211503117423 -0.13841742240261853 0.9902002000622324 1.620897267863362
  position -0.4239763877573109 -3.3326682394485783 0.235529302805811
  description "Default View"
}
TexturedBackground {
}
TexturedBackgroundLight {
}
RectangleArena {
  floorSize 3 3
}

Robot {
  translation -0.0678017 0.774844 0.29714
  rotation -0.9910285795542866 0.09307916051099348 -0.09590945931023395 -1.5963153071795864
  children [
    
    Shape {
      appearance PBRAppearance {
        baseColor 0.2 0.6 0.9
        roughness 0.3
        metalness 0.1
      }
      geometry Box {
        size 0.25 0.3 0.25
      }
    }
    DEF HEAD HingeJoint {
      jointParameters HingeJointParameters {
        axis -1 0 0
        anchor 0 0.15 0
      }
      device [
        RotationalMotor {
          name "tilt_motor"
          maxVelocity 3.14
        }
      ]
      endPoint Solid {
        translation 0 0.2 0
        rotation 0 1 0 1.5708
        children [
          Shape {
            appearance PBRAppearance {
              baseColor 0.9 0.3 0.2
              roughness 0.4
            }
            geometry Box {
              size 0.2 0.2 0.2
            }
          }
          Pose {
            translation 0 0.05 0.11
            children [
              Speaker {
              }
              Pose {
                translation -0.11 -0.03 -0.15
                children [
                  LED {
                    children [
                      Shape {
                        appearance PBRAppearance {
                          baseColor 0 0 0
                        }
                        geometry Sphere {
                          radius 0.025
                        }
                      }
                    ]
                    name "eye_led_left"
                  }
                ]
              }
              Pose {
                translation 0.04 -0.04 0
                children [
                  LED {
                    translation -0.13 0.01 -0.06
                    children [
                      Shape {
                        appearance PBRAppearance {
                          baseColor 0 0 0
                        }
                        geometry Sphere {
                          radius 0.025
                        }
                      }
                    ]
                    name "eye_led_right"
                  }
                ]
              }
            ]
          }
        ]
        name "head_solid"
      }
    }
    DEF WHEEL_SHAPE Shape {
      appearance PBRAppearance {
        baseColor 0.1 0.1 0.1
        roughness 0.4
        metalness 0
      }
      geometry Cylinder {
        height 0.04
        radius 0.05
      }
    }
    DEF LEFT_WHEEL HingeJoint {
      jointParameters HingeJointParameters {
        anchor -0.1 -0.15 0.1
      }
      device [
        RotationalMotor {
          name "left_wheel_motor"
        }
      ]
      endPoint Solid {
        translation -0.1 -0.15 0.1
        rotation 0 1 0 1.5708
        children [
          USE WHEEL_SHAPE
        ]
        name "left_wheel_solid"
        boundingObject Cylinder {
          height 0.04
          radius 0.05
        }
        physics Physics {
        }
      }
    }
    DEF RIGHT_WHEEL HingeJoint {
      jointParameters HingeJointParameters {
        anchor 0.1 -0.15 0.1
      }
      device [
        RotationalMotor {
          name "right_wheel_motor"
        }
      ]
      endPoint Solid {
        translation 0.1 -0.15 0.1
        rotation 0 1 0 1.5708
        children [
          USE WHEEL_SHAPE
        ]
        name "right_wheel_solid"
        boundingObject Cylinder {
          height 0.04
          radius 0.05
        }
        physics Physics {
        }
      }
    }
    DEF LEFT_REAR_WHEEL HingeJoint {
      jointParameters HingeJointParameters {
        anchor -0.1 -0.15 -0.1
      }
      device [
        RotationalMotor {
          name "left_rear_wheel_motor"
        }
      ]
      endPoint Solid {
        translation -0.1 -0.15 -0.1
        rotation 0 1 0 1.5708
        children [
          USE WHEEL_SHAPE
        ]
        name "left_rear_wheel_solid"
        boundingObject Cylinder {
          height 0.04
          radius 0.05
        }
        physics Physics {
        }
      }
    }
    DEF RIGHT_REAR_WHEEL HingeJoint {
      jointParameters HingeJointParameters {
        anchor 0.1 -0.15 -0.1
      }
      device [
        RotationalMotor {
          name "right_rear_wheel_motor"
        }
      ]
      endPoint Solid {
        translation 0.1 -0.15 -0.1
        rotation 0 1 0 1.5708
        children [
          USE WHEEL_SHAPE
        ]
        name "right_rear_wheel_solid"
        boundingObject Cylinder {
          height 0.04
          radius 0.05
        }
        physics Physics {
        }
      }
    }
  ]
  name "RoboDeskBuddy"
  boundingObject Box {
    size 0.25 0.3 0.25
  }
  physics Physics {
  }
  controller "desk_buddy_controller"
}
