#VRML_SIM R2025a utf8

EXTERNPROTO "https://raw.githubusercontent.com/cyberbotics/webots/R2025a/projects/objects/backgrounds/protos/TexturedBackground.proto"
EXTERNPROTO "https://raw.githubusercontent.com/cyberbotics/webots/R2025a/projects/objects/backgrounds/protos/TexturedBackgroundLight.proto"
EXTERNPROTO "https://raw.githubusercontent.com/cyberbotics/webots/R2025a/projects/objects/floors/protos/RectangleArena.proto"

WorldInfo {
  info [
    "Description: DeskBuddy"
  ]
  title "Table"
  basicTimeStep 16
  lineScale 0.2
}
Viewpoint {
  orientation 0.30544545223972824 -0.11888931700419249 -0.9447583849896991 4.49925579200068
  position 0.3303014132254629 -1.315847519212392 1.6113684888764879
  description "Default View"
}
TexturedBackground {
}
TexturedBackgroundLight {
}
RectangleArena {
  floorSize 3 3
}
Robot {
  translation -0.0256079 0.777102 0.795974
  rotation 0.9897494924047823 -0.10079181828520237 -0.10117782193365593 1.5811393417732627
  children [
    Solid {
      children [
        Transform {
          translation 0.03 -0.28 0
          rotation 0 1 0 4.692820414042842e-06
          scale 0.3 0.3 0.3
          children [
            CadShape {
              url [
                "../models/baymax_body.obj"
              ]
            }
          ]
        }
      ]
      boundingObject Box {
        size 0.25 0.3 0.25
      }
      physics Physics {
      }
    }
    DEF HEAD HingeJoint {
      jointParameters HingeJointParameters {
        axis -1 0 0
        anchor 0 0.15 0
      }
      device [
        RotationalMotor {
          name "tilt_motor"
          maxVelocity 3.14
        }
      ]
      endPoint Solid {
        translation 0.01 0.01999999999999999 0.01
        rotation 0 1 0 5.307156870259904e-06
        children [
          Transform {
            translation 0.02 -0.305 0
            scale 0.3 0.3 0.3
            children [
              CadShape {
                url [
                  "../models/baymax_head.obj"
                ]
              }
            ]
          }
          Pose {
            translation 0.19 0.2 -0.02
            rotation 0 1 0 1.309
            children [
              Speaker {
              }
              Pose {
                translation -0.12 -0.026 -0.2
                children [
                  LED {
                    translation -0.01 0 0
                    children [
                      Shape {
                        appearance PBRAppearance {
                          baseColor 0 0 0
                        }
                        geometry Sphere {
                          radius 0.025
                        }
                      }
                    ]
                    name "eye_led_left"
                  }
                ]
              }
              Pose {
                translation 0.03 -0.045 -0.07
                children [
                  LED {
                    translation -0.145 0.015 -0.079
                    children [
                      Shape {
                        appearance PBRAppearance {
                          baseColor 0 0 0
                        }
                        geometry Sphere {
                          radius 0.025
                        }
                      }
                    ]
                    name "eye_led_right"
                  }
                ]
              }
            ]
          }
        ]
        name "head_solid"
      }
    }
    DEF LEFT_ARM HingeJoint {
      jointParameters HingeJointParameters {
        position -3.3305178035016314e-07
        anchor -0.1 0.1 0
      }
      device [
        RotationalMotor {
          name "left_arm_motor"
        }
      ]
      endPoint Solid {
        translation 0.04999999999999935 0.040000000000003436 2.00341793196307e-08
        rotation -1 0 0 3.332000937312532e-07
        children [
          Transform {
            translation -0.029 -0.3172 0
            scale 0.3 0.3 0.3
            children [
              CadShape {
                url [
                  "../models/baymax_left_arm.obj"
                ]
              }
            ]
          }
        ]
        name "left_arm_solid"
        boundingObject Box {
          size 0.05 0.15 0.05
        }
        physics Physics {
        }
      }
    }
    DEF RIGHT_ARM HingeJoint {
      jointParameters HingeJointParameters {
        position -2.442980408000059e-07
        anchor 0.1 0.1 0
      }
      device [
        RotationalMotor {
          name "right_arm_motor"
        }
      ]
      endPoint Solid {
        translation -0.009999999999999565 0.04000000000000139 1.4757482306976733e-08
        rotation -0.9999999999999998 8.97868339310049e-11 1.0283094844148824e-08 5.5525173844527986e-06
        children [
          Transform {
            translation 0.05 -0.3172 0
            scale 0.3 0.3 0.3
            children [
              CadShape {
                url [
                  "../models/baymax_right_arm.obj"
                ]
              }
            ]
          }
        ]
        name "right_arm_solid"
        boundingObject Box {
          size 0.05 0.15 0.05
        }
        physics Physics {
        }
      }
    }
    DEF WHEEL_SHAPE Shape {
      appearance PBRAppearance {
        baseColor 0.1 0.1 0.1
        transparency 1
        roughness 0.4
        metalness 0
      }
      geometry Cylinder {
        height 0.04
        radius 0.05
      }
    }
    DEF LEFT_WHEEL HingeJoint {
      jointParameters HingeJointParameters {
        position -7.039204572380181
        anchor -0.1 -0.15 0.1
      }
      device [
        RotationalMotor {
          name "left_wheel_motor"
        }
      ]
      endPoint Solid {
        translation -0.05 -0.15 0.1
        rotation -0.346241116908506 0.8719132944020095 -0.3462431169091813 1.70744
        children [
          Transform {
            translation -8.15518e-08 -0.09 -0.08
            rotation 0 1 0 -1.5707953071795862
            scale 0.3 0.3 0.3
            children [
              CadShape {
                url [
                  "../models/baymax_left_wheel.obj"
                ]
              }
            ]
          }
        ]
        name "left_wheel_solid"
        boundingObject Cylinder {
          height 0.04
          radius 0.05
        }
        physics Physics {
        }
      }
    }
    DEF RIGHT_WHEEL HingeJoint {
      jointParameters HingeJointParameters {
        position 7.103223814092743
        anchor 0.1 -0.15 0.1
      }
      device [
        RotationalMotor {
          name "right_wheel_motor"
        }
      ]
      endPoint Solid {
        translation 0.10000000000000002 -0.15000000000000002 0.1000000000000001
        rotation -0.3702897468048841 -0.8519213575907775 -0.3702911069575683 4.5528059355991735
        children [
          Transform {
            translation -0.0633017 -0.0703612 -0.0999994
            rotation 0.44721312362157567 0.7745972141192264 -0.44721312362157567 1.82348
            scale 0.3 0.3 0.3
            children [
              CadShape {
                url [
                  "../models/baymax_right_wheel.obj"
                ]
              }
            ]
          }
        ]
        name "right_wheel_solid"
        boundingObject Cylinder {
          height 0.04
          radius 0.05
        }
        physics Physics {
        }
      }
    }
    DEF LEFT_REAR_WHEEL HingeJoint {
      jointParameters HingeJointParameters {
        position -7.103220310323706
        anchor -0.1 -0.15 -0.1
      }
      device [
        RotationalMotor {
          name "left_rear_wheel_motor"
        }
      ]
      endPoint Solid {
        translation -0.10000000000000006 -0.15000000000000002 -0.09999999999999999
        rotation 0.3702884589791945 -0.8519224771055149 0.37028981912714926 4.552807233006666
        children [
          Transform {
            translation 0.06364 -0.0687865 0.0699999
            rotation 0.3574058186283875 -0.8628565621288802 -0.35740681862788 -1.7177753071795863
            scale 0.3 0.3 0.3
            children [
              CadShape {
                url [
                  "../models/baymax_left_wheel.obj"
                ]
              }
            ]
          }
        ]
        name "left_rear_wheel_solid"
        boundingObject Cylinder {
          height 0.04
          radius 0.05
        }
        physics Physics {
        }
      }
    }
    DEF RIGHT_REAR_WHEEL HingeJoint {
      jointParameters HingeJointParameters {
        position 7.16719113277271
        anchor 0.1 -0.15 -0.1
      }
      device [
        RotationalMotor {
          name "right_rear_wheel_motor"
        }
      ]
      endPoint Solid {
        translation 0.09999999999999999 -0.15000000000000002 -0.09999999999999998
        rotation -0.3932805194294137 -0.8310594020913323 -0.3932819640320764 4.528378607056194
        children [
          Transform {
            translation 1.22354e-07 -0.09 0.12
            rotation 0 1 0 -1.5707953071795862
            scale 0.3 0.3 0.3
            children [
              CadShape {
                url [
                  "../models/baymax_right_wheel.obj"
                ]
              }
            ]
          }
        ]
        name "right_rear_wheel_solid"
        boundingObject Cylinder {
          height 0.04
          radius 0.05
        }
        physics Physics {
        }
      }
    }
  ]
  name "RoboDeskBuddy"
  boundingObject Box {
    size 0.25 0.3 0.25
  }
  physics Physics {
  }
  controller "desk_buddy_controller"
}
